Workbook

Sheet EDT
A2: Matriz Estructura de descomposición de tareas EDT — Khepri
A4: Etapas | B4: DIAS | C4: HORAS POR ACTIVIDAD O ENTREGABLE | I4: DICCIONARIO EDT
A5: Fase de Planificación (Fase 1 — 20%) | C5: Jefe de Proyecto | D5: Arquitecto de software | E5: Desarrollador frontend | F5: Calidad y testing | G5: Diseñador | I5: ROL | J5: SIGLA | K5: NOMBRE | L5: COSTO x HORA
A6: Organización del equipo | B6: 2 | C6: 4 | I6: Jefe de Proyecto | J6: JP | K6: Deyse Henriquez | L6: ='Costos Fases'!J4 -> 15000
A7: Acta de Constitución de proyecto | B7: 3 | C7: 12 | I7: Arquitecto de software | J7: AS | K7: Néstor Carvacho | L7: ='Costos Fases'!J5 -> 14000
A8: Aprobación del Acta | B8: 1 | C8: 2 | I8: Desarrollador frontend | J8: DF | K8: Gary Villegas | L8: ='Costos Fases'!J6 -> 13000
A9: Planilla de requerimientos (R.1–R.45) | B9: 2 | C9: 8 | D9: 4 | I9: Calidad y testing | J9: QA | K9: Néstor Carvacho | L9: ='Costos Fases'!J7 -> 14000
A10: Matriz EDT y cálculo de esfuerzo | B10: 2 | C10: 10 | I10: Diseñador | J10: DG | K10: Gary Villegas | L10: ='Costos Fases'!J8 -> 13000
A11: Carta Gantt | B11: 2 | C11: 6
A12: Documento Casos de uso extendido | B12: 7 | C12: 16 | D12: 12
A13: Documento Mockups (capturas de la app) | B13: 5 | G13: 32
A14: Informe ERS (IEEE 830) | B14: 4 | C14: 8 | D14: 16
A15: Documento de avance de sprints | B15: 3 | C15: 6
A16: Presentación Fase 1 (hito 10/09/2026) | B16: 2 | C16: 8 | D16: 4 | E16: 4
A17: Fase de diseño — modelo arquitectónico (Fase 2 — 20%) | C17: Jefe de Proyecto | D17: Arquitecto de software | E17: Desarrollador frontend | F17: Calidad y testing | G17: Diseñador
A18: Documento de arquitectura de software (DAS) | B18: 10 | C18: 12 | D18: 24
A19: Diccionario de datos (MySQL 8) | B19: 3 | D19: 12
A20: Matriz RACI | B20: 2 | C20: 8
A21: Matriz de riesgo | B21: 3 | C21: 10
A22: Matriz de control de cambios | B22: 2 | C22: 6
A23: Hito modelo arquitectónico (01/10/2026) | B23: 1 | C23: 4 | D23: 4
A24: Fase de Desarrollo (Fase 2 — 30%, 100% al 12/11/2026) | C24: Jefe de Proyecto | D24: Arquitecto de software | E24: Desarrollador frontend | F24: Calidad y testing | G24: Diseñador
A25: Seguimiento de sprints y coordinación | B25: 8 | C25: 28
A26: Ambiente de desarrollo (Git, .env, pytest, Vite) | B26: 3 | C26: 4 | D26: 12 | E26: 8
A27: Docker Compose y despliegue Railway | B27: 3 | D27: 4
A28: Scripts de esquema MySQL 8 | B28: 2 | D28: 4
A29: Módulo IAM y seguridad
A30: R.1 Autenticar usuario (JWT) | B30: 4 | D30: 6 | E30: 10
A31: R.2 Cerrar sesión | B31: 2 | D31: 3 | E31: 4
A32: R.3 Cambiar contraseña | B32: 2 | D32: 4 | E32: 6
A33: R.4 Bloqueo por intentos fallidos | B33: 2 | D33: 4
A34: R.7 Mantenedor de usuarios | B34: 4 | D34: 6 | E34: 12
A35: R.8 Mantenedor de roles y permisos | B35: 4 | D35: 6 | E35: 10
A36: R.9 Mantenedor de cargos | B36: 3 | D36: 5 | E36: 8
A37: R.10 Permisos de cargo | B37: 2 | D37: 4 | E37: 6
A38: R.27 Editar perfil de usuario | B38: 2 | D38: 2 | E38: 4
A39: R.29 Menú y rutas según permisos | B39: 2 | D39: 2 | E39: 4
A40: Módulo Tenant (multi-empresa)
A41: R.5 Mantenedor de empresas | B41: 4 | D41: 10 | E41: 10
A42: R.6 Filtro multi-empresa | B42: 3 | D42: 6 | E42: 10
...

Sheet Costos Fases
A2: SIGLA | B2: ROL | C2: NOMBRE | D2: VALOR HORA HH | E2: HORAS | F2: FASE PLANIFICACION | H2: COSTO POR HORA
A3: JP | B3: Jefe de Proyecto | C3: Deyse Henriquez | D3: =J4 -> 15000 | E3: =SUM(EDT!C6:C16) -> 80 | F3: =D3*E3 -> 1200000 | H3: ROL | I3: NOMBRE | J3: COSTO x HORA | K3: Sueldo mes
A4: AS | B4: Arquitecto de software | C4: Néstor Carvacho | D4: =J5 -> 14000 | E4: =SUM(EDT!D6:D16) -> 36 | F4: =D4*E4 -> 504000 | H4: Jefe de Proyecto | I4: Deyse Henriquez | J4: =K4/160 -> 15000 | K4: 2400000
A5: DF | B5: Desarrollador frontend | C5: Gary Villegas | D5: =J6 -> 13000 | E5: =SUM(EDT!E6:E16) -> 4 | F5: =D5*E5 -> 52000 | H5: Arquitecto de software | I5: Néstor Carvacho | J5: =K5/160 -> 14000 | K5: 2240000
A6: QA | B6: Calidad y testing | C6: Néstor Carvacho | D6: =J7 -> 14000 | E6: =SUM(EDT!F6:F16) -> 0 | F6: =D6*E6 -> 0 | H6: Desarrollador frontend | I6: Gary Villegas | J6: =K6/160 -> 13000 | K6: 2080000
A7: DG | B7: Diseñador | C7: Gary Villegas | D7: =J8 -> 13000 | E7: =SUM(EDT!G6:G16) -> 32 | F7: =D7*E7 -> 416000 | H7: Calidad y testing | I7: Néstor Carvacho | J7: =K7/160 -> 14000 | K7: 2240000
B8: TOTAL FASE PLANIFICACION | F8: =SUM(F3:F7) -> 2172000 | H8: Diseñador | I8: Gary Villegas | J8: =K8/160 -> 13000 | K8: 2080000
A11: SIGLA | B11: ROL | C11: NOMBRE | D11: VALOR HORA HH | E11: HORAS | F11: FASE DISEÑO | H11: COSTO HH POR ROL
A12: JP | B12: Jefe de Proyecto | C12: Deyse Henriquez | D12: =J4 -> 15000 | E12: =SUM(EDT!C18:C23) -> 40 | F12: =D12*E12 -> 600000 | H12: Jefe de Proyecto | I12: =F3+F12+F21+F30+F39 -> 3000000
A13: AS | B13: Arquitecto de software | C13: Néstor Carvacho | D13: =J5 -> 14000 | E13: =SUM(EDT!D18:D23) -> 40 | F13: =D13*E13 -> 560000 | H13: Arquitecto de software | I13: =F4+F13+F22+F31+F40 -> 3920000
A14: DF | B14: Desarrollador frontend | C14: Gary Villegas | D14: =J6 -> 13000 | E14: =SUM(EDT!E18:E23) -> 0 | F14: =D14*E14 -> 0 | H14: Desarrollador frontend | I14: =F5+F14+F23+F32+F41 -> 3640000
A15: QA | B15: Calidad y testing | C15: Néstor Carvacho | D15: =J7 -> 14000 | E15: =SUM(EDT!F18:F23) -> 0 | F15: =D15*E15 -> 0 | H15: Calidad y testing | I15: =F6+F15+F24+F33+F42 -> 840000
A16: DG | B16: Diseñador | C16: Gary Villegas | D16: =J8 -> 13000 | E16: =SUM(EDT!G18:G23) -> 0 | F16: =D16*E16 -> 0 | H16: Diseñador | I16: =F7+F16+F25+F34+F43 -> 780000
B17: TOTAL FASE DISEÑO | F17: =SUM(F12:F16) -> 1160000 | H17: TOTAL HH | I17: =SUM(I12:I16) -> 12180000
A20: SIGLA | B20: ROL | C20: NOMBRE | D20: VALOR HORA HH | E20: HORAS | F20: FASE DESARROLLO | H20: COSTO POR FASE
A21: JP | B21: Jefe de Proyecto | C21: Deyse Henriquez | D21: =J4 -> 15000 | E21: =SUM(EDT!C25:C67) -> 36 | F21: =D21*E21 -> 540000 | H21: Fase de Planificación | I21: =F8 -> 2172000
A22: AS | B22: Arquitecto de software | C22: Néstor Carvacho | D22: =J5 -> 14000 | E22: =SUM(EDT!D25:D67) -> 176 | F22: =D22*E22 -> 2464000 | H22: Fase de Análisis y Diseño | I22: =F17 -> 1160000
A23: DF | B23: Desarrollador frontend | C23: Gary Villegas | D23: =J6 -> 13000 | E23: =SUM(EDT!E25:E67) -> 252 | F23: =D23*E23 -> 3276000 | H23: Fase de Desarrollo | I23: =F26 -> 6280000
A24: QA | B24: Calidad y testing | C24: Néstor Carvacho | D24: =J7 -> 14000 | E24: =SUM(EDT!F25:F67) -> 0 | F24: =D24*E24 -> 0 | H24: Fase de Pruebas y QA | I24: =F35 -> 1624000
A25: DG | B25: Diseñador | C25: Gary Villegas | D25: =J8 -> 13000 | E25: =SUM(EDT!G25:G67) -> 0 | F25: =D25*E25 -> 0 | H25: Fase de Implementación y Cierre | I25: =F44 -> 944000
B26: TOTAL FASE DESARROLLO | F26: =SUM(F21:F25) -> 6280000 | H26: TOTAL HH FASES (mano de obra) | I26: =SUM(I21:I25) -> 12180000
A29: SIGLA | B29: ROL | C29: NOMBRE | D29: VALOR HORA HH | E29: HORAS | F29: FASE PRUEBAS QA
A30: JP | B30: Jefe de Proyecto | C30: Deyse Henriquez | D30: =J4 -> 15000 | E30: =SUM(EDT!C69:C72) -> 16 | F30: =D30*E30 -> 240000
A31: AS | B31: Arquitecto de software | C31: Néstor Carvacho | D31: =J5 -> 14000 | E31: =SUM(EDT!D69:D72) -> 24 | F31: =D31*E31 -> 336000
A32: DF | B32: Desarrollador frontend | C32: Gary Villegas | D32: =J6 -> 13000 | E32: =SUM(EDT!E69:E72) -> 16 | F32: =D32*E32 -> 208000
A33: QA | B33: Calidad y testing | C33: Néstor Carvacho | D33: =J7 -> 14000 | E33: =SUM(EDT!F69:F72) -> 60 | F33: =D33*E33 -> 840000
A34: DG | B34: Diseñador | C34: Gary Villegas | D34: =J8 -> 13000 | E34: =SUM(EDT!G69:G72) -> 0 | F34: =D34*E34 -> 0
B35: TOTAL FASE PRUEBAS QA | F35: =SUM(F30:F34) -> 1624000
A38: SIGLA | B38: ROL | C38: NOMBRE | D38: VALOR HORA HH | E38: HORAS | F38: FASE IMPLEMENTACION Y CIERRE
A39: JP | B39: Jefe de Proyecto | C39: Deyse Henriquez | D39: =J4 -> 15000 | E39: =SUM(EDT!C74:C77) -> 28 | F39: =D39*E39 -> 420000
A40: AS | B40: Arquitecto de software | C40: Néstor Carvacho | D40: =J5 -> 14000 | E40: =SUM(EDT!D74:D77) -> 4 | F40: =D40*E40 -> 56000
A41: DF | B41: Desarrollador frontend | C41: Gary Villegas | D41: =J6 -> 13000 | E41: =SUM(EDT!E74:E77) -> 8 | F41: =D41*E41 -> 104000
A42: QA | B42: Calidad y testing | C42: Néstor Carvacho | D42: =J7 -> 14000 | E42: =SUM(EDT!F74:F77) -> 0 | F42: =D42*E42 -> 0
A43: DG | B43: Diseñador | C43: Gary Villegas | D43: =J8 -> 13000 | E43: =SUM(EDT!G74:G77) -> 28 | F43: =D43*E43 -> 364000
B44: TOTAL FASE IMPLEMENTACION | F44: =SUM(F39:F43) -> 944000
